Workbook

Sheet DadosBrutos
A1: Filial | B1: Cliente | C1: PV | D1: NF | E1: Emissão NF | F1: Transport. | G1: Dt. Romaneio | H1: Dt. Entrega Real | I1: R$ NF
A2: 101 | B2: FUNDACAO ANTONIO PRUDENTE | C2: 61968 | D2: 170520 | E2: 46205 | F2: CARRO PROPRIO | G2: 46210 | H2: 46210 | I2: R$ 984,00
A3: 101 | B3: SOCIEDADE BENEF - HOSP SIRIO LIBANES | C3: 61969 | D3: 170700 | E3: 46206 | F3: CARRO PROPRIO | G3: 46213 | H3: 46213 | I3: R$ 8.642,70
A4: 101 | B4: SOCIEDADE BENEF - HOSP SIRIO LIBANES | C4: 61970 | D4: 170701 | E4: 46206 | F4: CARRO PROPRIO | G4: 46213 | H4: 46213 | I4: R$ 10.578,20
A5: 101 | B5: SOCIEDADE BENEF - HOSP SIRIO LIBANES | C5: 61970 | D5: 172315 | E5: 46224 | F5: CARRO PROPRIO | G5: 46226 | H5: 46226 | I5: R$ 8.000,00
A6: 101 | B6: SOCIEDADE BENEF - HOSP SIRIO LIBANES | C6: 61971 | D6: 170702 | E6: 46206 | F6: CARRO PROPRIO | G6: 46213 | H6: 46213 | I6: R$ 3.960,00
A7: 101 | B7: PREVENT SENIOR ATENDIMENTO A SAUDE LTDA. | C7: 61972 | D7: 170703 | E7: 46206 | F7: CARRO PROPRIO | G7: 46211 | H7: 46211 | I7: R$ 12.875,46
A8: 101 | B8: SOCIEDADE BENEF - HOSP SIRIO LIBANES | C8: 61975 | D8: 170691 | E8: 46206 | F8: CARRO PROPRIO | G8: 46210 | H8: 46210 | I8: R$ 3.608,00
A9: 101 | B9: SOCIEDADE BENEF - HOSP SIRIO LIBANES | C9: 61976 | D9: 172316 | E9: 46224 | F9: CARRO PROPRIO | G9: 46226 | H9: 46226 | I9: R$ 4.000,00
A10: 101 | B10: SOCIEDADE BENEF - HOSP SIRIO LIBANES | C10: 61977 | D10: 171171 | E10: 46213 | F10: CARRO PROPRIO | G10: 46231 | H10: 46231 | I10: R$ 3.077,00
A11: 101 | B11: SOCIEDADE BENEF - HOSP SIRIO LIBANES | C11: 61978 | D11: 171244 | E11: 46213 | F11: CARRO PROPRIO | G11: 46231 | H11: 46231 | I11: R$ 11.895,00
A12: 101 | B12: DIAGNOSTICOS DA AMERICA SA | C12: 61979 | D12: 170498 | E12: 46205 | F12: CARRO PROPRIO | G12: 46206 | H12: 46206 | I12: R$ 1.371,85
A13: 101 | B13: FUNDACAO ANTONIO PRUDENTE | C13: 61980 | D13: 170521 | E13: 46205 | F13: CARRO PROPRIO | G13: 46210 | H13: 46210 | I13: R$ 32.166,05
A14: 101 | B14: FUNDACAO ANTONIO PRUDENTE | C14: 61982 | D14: 170523 | E14: 46205 | F14: CARRO PROPRIO | G14: 46210 | H14: 46210 | I14: R$ 2.220,27
A15: 101 | B15: FUNDACAO ANTONIO PRUDENTE | C15: 61982 | D15: 172540 | E15: 46226 | F15: CARRO PROPRIO | G15: 46231 | I15: R$ 2.245,35
A16: 101 | B16: DIAGNOSTICOS DA AMERICA S.A . | C16: 61983 | D16: 170920 | E16: 46210 | F16: CARRO PROPRIO | G16: 46218 | H16: 46218 | I16: R$ 30,20
A17: 101 | B17: DIAGNOSTICOS DA AMERICA S.A . | C17: 61983 | D17: 170920 | E17: 46210 | F17: CARRO PROPRIO | G17: 46218 | H17: 46218 | I17: R$ 3.281,40
A18: 101 | B18: DIAGNOSTICOS DA AMERICA S.A . | C18: 61984 | D18: 170499 | E18: 46205 | F18: RISSO | G18: 46206 | H18: 46210 | I18: R$ 965,65
A19: 101 | B19: PREVILAB | C19: 61985 | D19: 170921 | E19: 46210 | F19: RISSO | G19: 46213 | H19: 46216 | I19: R$ 583,00
A20: 101 | B20: PREVILAB | C20: 61985 | D20: 170921 | E20: 46210 | F20: RISSO | G20: 46213 | H20: 46216 | I20: R$ 12,53
A21: 101 | B21: DIVISAO LAVOISIER - SANTANA | C21: 61986 | D21: 170500 | E21: 46205 | F21: CARRO PROPRIO | G21: 46210 | H21: 46210 | I21: R$ 4.938,40
A22: 101 | B22: FUNDACAO HOSPITALAR SAO LUCAS | C22: 61988 | D22: 172016 | E22: 46220 | F22: ARLETE TRANSPOR | G22: 46223 | H22: 46225 | I22: R$ 23.280,00
A23: 101 | B23: FUNDACAO HOSPITALAR SAO LUCAS | C23: 61989 | D23: 172017 | E23: 46220 | F23: ARLETE TRANSPOR | G23: 46223 | H23: 46225 | I23: R$ 14.666,40
A24: 101 | B24: ASSOCIACAO BENEFICENTE SIRIA | C24: 61990 | D24: 170459 | E24: 46204 | F24: CARRO PROPRIO | G24: 46232 | H24: 46232 | I24: R$ 2.408,00
A25: 101 | B25: DIAGNOSTICOS DA AMERICA SA | C25: 61991 | D25: 172351 | E25: 46224 | F25: BTA TRANSPORTE | G25: 46226 | H25: 46227 | I25: R$ 20.197,50
A26: 101 | B26: DIAGNOSTICOS DA AMERICA SA | C26: 61992 | D26: 172352 | E26: 46224 | F26: BTA TRANSPORTE | G26: 46226 | H26: 46227 | I26: R$ 2.452,50
A27: 101 | B27: IGESP SA CENTRO MEDICO E CIRURGICO INST GASTROENT DE SP | C27: 61993 | D27: 170468 | E27: 46205 | F27: RISSO | G27: 46209 | H27: 46211 | I27: R$ 1.029,00
... A80: 101 | B80: DASA - SAO MARCOS | C80: 62042 | D80: 170599 | E80: 46205 | F80: BTA TRANSPORTE | G80: 46209 | H80: 46212 | I80: R$ 970,08
A81: 101 | B81: ASSOCIACAO CONGREGACAO DE SANTA CATARINA | C81: 62043 | D81: 170696 | E81: 46206 | F81: CARRO PROPRIO | I81: R$ 21.713,12
A82: 101 | B82: DASA - SAO MARCOS | C82: 62044 | D82: 173749 | E82: 46250 | F82: BTA TRANSPORTE | G82: 46251 | H82: 46254 | I82: R$ 4.059,00
A83: 101 | B83: DIAGNOSTICOS DA AMERICA SA | C83: 62046 | D83: 171487 | E83: 46217 | F83: ARLETE TRANSPOR | G83: 46218 | H83: 46224 | I83: R$ 86,14
A84: 101 | B84: DIAGNOSTICOS DA AMERICA SA | C84: 62046 | D84: 170600 | E84: 46205 | F84: ARLETE TRANSPOR | G84: 46209 | H84: 46213 | I84: R$ 1.393,78
A85: 101 | B85: DIAGNOSTICOS DA AMERICA SA | C85: 62046 | D85: 171523 | E85: 46217 | F85: ARLETE TRANSPOR | G85: 46218 | H85: 46224 | I85: R$ 71,22
A86: 101 | B86: DIAGNOSTICOS DA AMERICA SA | C86: 62047 | D86: 172225 | E86: 46223 | F86: ARLETE TRANSPOR | G86: 46225 | H86: 46238 | I86: R$ 763,60
A87: 101 | B87: RUGGERI E PIVA LTDA | C87: 62048 | D87: 170601 | E87: 46205 | F87: ARLETE TRANSPOR | G87: 46206 | H87: 46213 | I87: R$ 645,13
A88: 101 | B88: CASA DE SAUDE E MATERNIDADE SANTA MARTHA SA | C88: 62049 | D88: 171405 | E88: 46216 | F88: CARRO PROPRIO | G88: 46232 | H88: 46232 | I88: R$ 10.025,82
A89: 101 | B89: RUGGERI E PIVA LTDA | C89: 62050 | D89: 173750 | E89: 46250 | F89: ARLETE TRANSPOR | G89: 46251 | H89: 46255 | I89: R$ 738,00
A90: 101 | B90: SOCIEDADE BENEF - HOSP SIRIO LIBANES | C90: 62051 | D90: 170524 | E90: 46205 | F90: CARRO PROPRIO | G90: 46209 | H90: 46209 | I90: R$ 3.000,00
A91: 101 | B91: DIAGNOSTICOS DA AMERICA SA | C91: 62052 | D91: 170959 | E91: 46210 | F91: ARLETE TRANSPOR | G91: 46217 | H91: 46219 | I91: R$ 371,96
A92: 101 | B92: DIAGNOSTICOS DA AMERICA SA | C92: 62052 | D92: 170602 | E92: 46205 | F92: ARLETE TRANSPOR | G92: 46209 | H92: 46213 | I92: R$ 1.941,35
...

Sheet Estátisticas
A1: Transportadora | B1: Total de Notas Fiscais | C1: Total Entregues (Concluídas) | D1: Total Não Entregues (Pendentes)
A2: {=UNIQUE(DadosBrutos!F2:F6895)} -> CARRO PROPRIO | B2: =COUNTIF(DadosBrutos!F:F, A2) -> 4356 | C2: =SUMPRODUCT((DadosBrutos!$F:$F=A2)*(DadosBrutos!$G:$G<>"")) -> 4162 | D2: =SUMPRODUCT((DadosBrutos!$F:$F=A2)*(DadosBrutos!$G:$G="")) -> 194
A3: RISSO | B3: =COUNTIF(DadosBrutos!F:F, A3) -> 1354 | C3: =SUMPRODUCT((DadosBrutos!$F:$F=A3)*(DadosBrutos!$G:$G<>"")) -> 1335 | D3: =SUMPRODUCT((DadosBrutos!$F:$F=A3)*(DadosBrutos!$G:$G="")) -> 19
A4: ARLETE TRANSPOR | B4: =COUNTIF(DadosBrutos!F:F, A4) -> 119 | C4: =SUMPRODUCT((DadosBrutos!$F:$F=A4)*(DadosBrutos!$G:$G<>"")) -> 119 | D4: =SUMPRODUCT((DadosBrutos!$F:$F=A4)*(DadosBrutos!$G:$G="")) -> 0
A5: BTA TRANSPORTE | B5: =COUNTIF(DadosBrutos!F:F, A5) -> 311 | C5: =SUMPRODUCT((DadosBrutos!$F:$F=A5)*(DadosBrutos!$G:$G<>"")) -> 306 | D5: =SUMPRODUCT((DadosBrutos!$F:$F=A5)*(DadosBrutos!$G:$G="")) -> 5
A6: PACIFICO LOG | B6: =COUNTIF(DadosBrutos!F:F, A6) -> 162 | C6: =SUMPRODUCT((DadosBrutos!$F:$F=A6)*(DadosBrutos!$G:$G<>"")) -> 160 | D6: =SUMPRODUCT((DadosBrutos!$F:$F=A6)*(DadosBrutos!$G:$G="")) -> 2
A7: BROS LOGÍSTICA | B7: =COUNTIF(DadosBrutos!F:F, A7) -> 73 | C7: =SUMPRODUCT((DadosBrutos!$F:$F=A7)*(DadosBrutos!$G:$G<>"")) -> 72 | D7: =SUMPRODUCT((DadosBrutos!$F:$F=A7)*(DadosBrutos!$G:$G="")) -> 1
A8: SCHREIBER LOGIS | B8: =COUNTIF(DadosBrutos!F:F, A8) -> 68 | C8: =SUMPRODUCT((DadosBrutos!$F:$F=A8)*(DadosBrutos!$G:$G<>"")) -> 60 | D8: =SUMPRODUCT((DadosBrutos!$F:$F=A8)*(DadosBrutos!$G:$G="")) -> 8
A9: CORREIOS | B9: =COUNTIF(DadosBrutos!F:F, A9) -> 47 | C9: =SUMPRODUCT((DadosBrutos!$F:$F=A9)*(DadosBrutos!$G:$G<>"")) -> 46 | D9: =SUMPRODUCT((DadosBrutos!$F:$F=A9)*(DadosBrutos!$G:$G="")) -> 1
A10: Não Definida | B10: =COUNTIF(DadosBrutos!F:F, A10) -> 290 | C10: =SUMPRODUCT((DadosBrutos!$F:$F=A10)*(DadosBrutos!$G:$G<>"")) -> 266 | D10: =SUMPRODUCT((DadosBrutos!$F:$F=A10)*(DadosBrutos!$G:$G="")) -> 24
A11: RETIRA MATRIZ | B11: =COUNTIF(DadosBrutos!F:F, A11) -> 40 | C11: =SUMPRODUCT((DadosBrutos!$F:$F=A11)*(DadosBrutos!$G:$G<>"")) -> 28 | D11: =SUMPRODUCT((DadosBrutos!$F:$F=A11)*(DadosBrutos!$G:$G="")) -> 12
A12: ARGIUS TRANSPOR | B12: =COUNTIF(DadosBrutos!F:F, A12) -> 1 | C12: =SUMPRODUCT((DadosBrutos!$F:$F=A12)*(DadosBrutos!$G:$G<>"")) -> 1 | D12: =SUMPRODUCT((DadosBrutos!$F:$F=A12)*(DadosBrutos!$G:$G="")) -> 0
A13: CARRO TECNICA | B13: =COUNTIF(DadosBrutos!F:F, A13) -> 52 | C13: =SUMPRODUCT((DadosBrutos!$F:$F=A13)*(DadosBrutos!$G:$G<>"")) -> 34 | D13: =SUMPRODUCT((DadosBrutos!$F:$F=A13)*(DadosBrutos!$G:$G="")) -> 18
A14: VAZ FIEL TRANSP | B14: =COUNTIF(DadosBrutos!F:F, A14) -> 16 | C14: =SUMPRODUCT((DadosBrutos!$F:$F=A14)*(DadosBrutos!$G:$G<>"")) -> 16 | D14: =SUMPRODUCT((DadosBrutos!$F:$F=A14)*(DadosBrutos!$G:$G="")) -> 0
... A19: TELE CARGA | B19: =COUNTIF(DadosBrutos!F:F, A19) -> 1 | C19: =SUMPRODUCT((DadosBrutos!$F:$F=A19)*(DadosBrutos!$G:$G<>"")) -> 1 | D19: =SUMPRODUCT((DadosBrutos!$F:$F=A19)*(DadosBrutos!$G:$G="")) -> 0
